Workbook

Sheet Ringkasan
A1: Eval v1.0: 1 agent vs multi-agent
A2: Hanya soal yang dijalankan di keduanya (kolom 'Dibandingkan' = Ya). Skor 0-3 dari penilai LLM (exact match untuk angka database). Model: DeepSeek V4 (pro untuk ketua/pengecek/penilai, flash untuk child).
A4: Kelompok | B4: Jumlah soal | C4: Skor 1 agent | D4: Skor multi-agent | E4: Selisih
A5: Simple lookups | B5: =COUNTIFS(Perbandingan!$B$2:$B$23,A5,Perbandingan!$E$2:$E$23,"Ya") | C5: =IF(B5=0,"-",AVERAGEIFS(Perbandingan!$F$2:$F$23,Perbandingan!$B$2:$B$23,A5,Perbandingan!$E$2:$E$23,"Ya")) | D5: =IF(B5=0,"-",AVERAGEIFS(Perbandingan!$G$2:$G$23,Perbandingan!$B$2:$B$23,A5,Perbandingan!$E$2:$E$23,"Ya")) | E5: =IF(B5=0,"-",D5-C5)
A6: Multi-part | B6: =COUNTIFS(Perbandingan!$B$2:$B$23,A6,Perbandingan!$E$2:$E$23,"Ya") | C6: =IF(B6=0,"-",AVERAGEIFS(Perbandingan!$F$2:$F$23,Perbandingan!$B$2:$B$23,A6,Perbandingan!$E$2:$E$23,"Ya")) | D6: =IF(B6=0,"-",AVERAGEIFS(Perbandingan!$G$2:$G$23,Perbandingan!$B$2:$B$23,A6,Perbandingan!$E$2:$E$23,"Ya")) | E6: =IF(B6=0,"-",D6-C6)
A7: News + papers | B7: =COUNTIFS(Perbandingan!$B$2:$B$23,A7,Perbandingan!$E$2:$E$23,"Ya") | C7: =IF(B7=0,"-",AVERAGEIFS(Perbandingan!$F$2:$F$23,Perbandingan!$B$2:$B$23,A7,Perbandingan!$E$2:$E$23,"Ya")) | D7: =IF(B7=0,"-",AVERAGEIFS(Perbandingan!$G$2:$G$23,Perbandingan!$B$2:$B$23,A7,Perbandingan!$E$2:$E$23,"Ya")) | E7: =IF(B7=0,"-",D7-C7)
A8: Judgement (debate) | B8: =COUNTIFS(Perbandingan!$B$2:$B$23,A8,Perbandingan!$E$2:$E$23,"Ya") | C8: =IF(B8=0,"-",AVERAGEIFS(Perbandingan!$F$2:$F$23,Perbandingan!$B$2:$B$23,A8,Perbandingan!$E$2:$E$23,"Ya")) | D8: =IF(B8=0,"-",AVERAGEIFS(Perbandingan!$G$2:$G$23,Perbandingan!$B$2:$B$23,A8,Perbandingan!$E$2:$E$23,"Ya")) | E8: =IF(B8=0,"-",D8-C8)
A9: Semua | B9: =COUNTIFS(Perbandingan!$E$2:$E$23,"Ya") | C9: =AVERAGEIFS(Perbandingan!$F$2:$F$23,Perbandingan!$E$2:$E$23,"Ya") | D9: =AVERAGEIFS(Perbandingan!$G$2:$G$23,Perbandingan!$E$2:$E$23,"Ya") | E9: =D9-C9
A11: Metrik | C11: 1 agent | D11: Multi-agent
A12: Lulus (skor 2+) | C12: =COUNTIFS(Perbandingan!$E$2:$E$23,"Ya",Perbandingan!$F$2:$F$23,">=2") | D12: =COUNTIFS(Perbandingan!$E$2:$E$23,"Ya",Perbandingan!$G$2:$G$23,">=2")
A13: Biaya rata-rata / soal ($) | C13: =AVERAGEIFS(Perbandingan!$I$2:$I$23,Perbandingan!$E$2:$E$23,"Ya") | D13: =AVERAGEIFS(Perbandingan!$J$2:$J$23,Perbandingan!$E$2:$E$23,"Ya")
A14: Waktu rata-rata / soal (dtk) | C14: =AVERAGEIFS(Perbandingan!$K$2:$K$23,Perbandingan!$E$2:$E$23,"Ya") | D14: =AVERAGEIFS(Perbandingan!$L$2:$L$23,Perbandingan!$E$2:$E$23,"Ya")
A15: Total biaya ($) | C15: =SUMIFS(Perbandingan!$I$2:$I$23,Perbandingan!$E$2:$E$23,"Ya") | D15: =SUMIFS(Perbandingan!$J$2:$J$23,Perbandingan!$E$2:$E$23,"Ya")
A16: Mode dipilih benar | D16: =COUNTIFS(Perbandingan!$O$2:$O$23,"Ya")&"/"&(COUNTIFS(Perbandingan!$O$2:$O$23,"Ya")+COUNTIFS(Perbandingan!$O$2:$O$23,"Tidak"))
A18: Catatan:
A19: - Biaya dari hitungan internal dan lebih rendah dari tagihan asli: token percobaan ulang yang terpotong belum tercatat (bug, sudah diperbaiki).
A20: - 22 soal, 1 kali jalan per soal; selisih 0.1-0.2 masih dalam batas noise.
A21: - 5 soal terakhir multi-agent dijalankan belakangan (saldo API sempat habis); 2 soal debat di antaranya dijalankan ulang setelah perbaikan balasan kosong.

Sheet Perbandingan
A1: ID | B1: Kelompok | C1: Pertanyaan | D1: Kriteria penilaian | E1: Dibandingkan | F1: Skor 1 agent | G1: Skor multi-agent | H1: Selisih | I1: Biaya 1 agent ($) | J1: Biaya multi-agent ($) | K1: Waktu 1 agent (dtk) | L1: Waktu multi-agent (dtk) | M1: Mode diharapkan | N1: Mode dipilih | O1: Mode benar? | P1: Alasan penilai (1 agent) | Q1: Alasan penilai (multi-agent) | R1: Catatan
A2: db-artists | B2: Simple lookups | C2: Which artist has the most tracks in the chinook database, and how many? | D2: Harus memuat: Iron Maiden, 213 | E2: =IF(AND(ISNUMBER(F2),ISNUMBER(G2)),"Ya","Tidak") | F2: 3 | G2: 3 | H2: =IF(E2="Ya",G2-F2,"") | I2: 0.00079 | J2: 0.00734 | K2: 13.1 | L2: 96.9 | M2: facts | N2: facts | O2: =IF(OR(N2="",M2="bebas"),"",IF(M2=N2,"Ya","Tidak")) | P2: all expected values present | Q2: all expected values present
A3: db-revenue | B3: Simple lookups | C3: What are the top 3 countries by total invoice revenue in the chinook database? | D3: Harus memuat: USA|United States, Canada, France | E3: =IF(AND(ISNUMBER(F3),ISNUMBER(G3)),"Ya","Tidak") | F3: 3 | G3: 3 | H3: =IF(E3="Ya",G3-F3,"") | I3: 0.00075 | J3: 0.00273 | K3: 11.3 | L3: 29.5 | M3: facts | N3: facts | O3: =IF(OR(N3="",M3="bebas"),"",IF(M3=N3,"Ya","Tidak")) | P3: all expected values present | Q3: all expected values present | R3: Awalnya 1/3 karena pengecek cuma menerima 'USA'; jawabannya 'United States' (benar). Dinilai ulang setelah pengecek diperbaiki.
A4: db-employees | B4: Simple lookups | C4: How many employees are in the chinook database? | D4: Harus memuat: 8 | E4: =IF(AND(ISNUMBER(F4),ISNUMBER(G4)),"Ya","Tidak") | F4: 3 | G4: 3 | H4: =IF(E4="Ya",G4-F4,"") | I4: 0.00061 | J4: 0.00161 | K4: 9 | L4: 19.7 | M4: facts | N4: facts | O4: =IF(OR(N4="",M4="bebas"),"",IF(M4=N4,"Ya","Tidak")) | P4: all expected values present | Q4: all expected values present
A5: db-northwind | B5: Simple lookups | C5: How many products are in the northwind database? | D5: Harus memuat: 77 | E5: =IF(AND(ISNUMBER(F5),ISNUMBER(G5)),"Ya","Tidak") | F5: 3 | G5: 3 | H5: =IF(E5="Ya",G5-F5,"") | I5: 0.00063 | J5: 0.00152 | K5: 9.3 | L5: 16.9 | M5: facts | N5: facts | O5: =IF(OR(N5="",M5="bebas"),"",IF(M5=N5,"Ya","Tidak")) | P5: all expected values present | Q5: all expected values present
A6: web-ojk | B6: Simple lookups | C6: What did Indonesia's OJK say caused the rise in bad loans at digital lending platforms, and roughly what was the TWP90 level in 2026? | D6: Names borrower repayment capacity as the main driver, cites OJK, and gives a TWP90 figure around 4-5 percent. | E6: =IF(AND(ISNUMBER(F6),ISNUMBER(G6)),"Ya","Tidak") | F6: 3 | G6: 3 | H6: =IF(E6="Ya",G6-F6,"") | I6: 0.00328 | J6: 0.02926 | K6: 25 | L6: 451 | M6: facts | N6: facts | O6: =IF(OR(N6="",M6="bebas"),"",IF(M6=N6,"Ya","Tidak")) | P6: The answer identifies borrower repayment capacity as the main driver with OJK citations and provides 2026 TWP90 figures around 4.4–4.7 percent, matching the requested 4–5 percent range. | Q6: The answer names reduced borrower repayment capacity as the main driver with OJK citations and gives a TWP90 level around 4.3-4.7% in 2026, matching the criterion.
A7: web-mcp | B7: Simple lookups | C7: What is the Model Context Protocol and how widely is it adopted? | D7: Explains MCP as a standard for connecting AI models to tools and data, and gives an adoption figure such as thousands of public servers. | E7: =IF(AND(ISNUMBER(F7),ISNUMBER(G7)),"Ya","Tidak") | F7: 3 | G7: 2 | H7: =IF(E7="Ya",G7-F7,"") | I7: 0.00726 | J7: 0.05568 | K7: 45 | L7: 469.7 | M7: facts | N7: facts | O7: =IF(OR(N7="",M7="bebas"),"",IF(M7=N7,"Ya","Tidak")) | P7: The answer clearly explains MCP as a standard for connecting AI models to tools and data and provides well-cited adoption figures including thousands of public servers, with appropriate nuance about usage quality. | Q7: The answer thoroughly explains MCP as a standard for connecting AI models to tools and data with citations, but it cuts off before providing the required adoption figure such as thousands of public servers. | R7: Bug: laporan terpotong di tengah kalimat. Sudah diperbaiki setelah eval.
A8: web-deepseek | B8: Simple lookups | C8: How does DeepSeek V4 pricing compare to Anthropic's Claude models? | D8: Gives per-million-token prices for both and correctly concludes DeepSeek is roughly an order of magnitude cheaper. | E8: =IF(AND(ISNUMBER(F8),ISNUMBER(G8)),"Ya","Tidak") | F8: 3 | G8: 3 | H8: =IF(E8="Ya",G8-F8,"") | I8: 0.02816 | J8: 0.05863 | K8: 295.8 | L8: 769.1 | M8: facts | N8: facts | O8: =IF(OR(N8="",M8="bebas"),"",IF(M8=N8,"Ya","Tidak")) | P8: Provides cited per-million-token prices for both DeepSeek V4 and Claude models and correctly concludes DeepSeek is roughly an order of magnitude cheaper for comparable mid/top tiers, with the low-end caveat supported. | Q8: The answer provides cited per-million-token prices for both DeepSeek V4 and Anthropic Claude models and correctly concludes DeepSeek is generally much cheaper, often by roughly an order of magnitude, while noting caveats.
A9: mixed-genre | B9: Simple lookups | C9: Which music genre has the most tracks in the chinook database, and what is that genre's real-world popularity today? | D9: Reports Rock as the top genre with a track count from the database, then adds web-sourced context on the genre's current popularity. | E9: =IF(AND(ISNUMBER(F9),ISNUMBER(G9)),"Ya","Tidak") | F9: 3 | G9: 3 | H9: =IF(E9="Ya",G9-F9,"") | I9: 0.00405 | J9: 0.04207 | K9: 40 | L9: 562.2 | M9: facts | N9: facts | O9: =IF(OR(N9="",M9="bebas"),"",IF(M9=N9,"Ya","Tidak")) | P9: The answer correctly identifies Rock as the Chinook top genre with 1,297 tracks and adds cited, current real-world popularity context showing rock as a strong second genre rather than the top genre. | Q9: The answer correctly identifies Rock as the top genre with 1,297 tracks and provides well-cited, web-sourced context on rock's current popularity across streaming, sales, and charts.
A10: unanswerable | B10: Simple lookups | C10: What was the exact revenue of the chinook music store in the third quarter of 2027? | D10: States that the data does not exist or the date is in the future, rather than inventing a figure. | E10: =IF(AND(ISNUMBER(F10),ISNUMBER(G10)),"Ya","Tidak") | F10: 3 | G10: 2 | H10: =IF(E10="Ya",G10-F10,"") | I10: 0.0014 | J10: 0.00784 | K10: 17.8 | L10: 111.3 | M10: facts | N10: facts | O10: =IF(OR(N10="",M10="bebas"),"",IF(M10=N10,"Ya","Tidak")) | P10: The answer correctly states that no Q3 2027 data exists because the invoice table's latest date is 2025-12-22, and it cites the internal database rather than inventing a revenue figure. | Q10: The answer correctly notes the absence of invoice data for Q3 2027 but incorrectly asserts an exact revenue of $0.00 rather than simply stating the data does not exist or is unavailable.
A11: contradiction | B11: Simple lookups | C11: Is Groq's built-in web search a good choice for a deep research agent that needs citations? | D11: Notes that Groq's built-in search returns answers without exposing source URLs, which makes citation hard, and weighs that against its convenience. | E11: =IF(AND(ISNUMBER(F11),ISNUMBER(G11)),"Ya","Tidak") | F11: 2 | G11: 2 | H11: =IF(E11="Ya",G11-F11,"") | I11: 0.01006 | J11: 0.02344 | K11: 68.2 | L11: 254.1 | M11: bebas | N11: debate | O11: =IF(OR(N11="",M11="bebas"),"",IF(M11=N11,"Ya","Tidak")) | P11: The answer gives a well-cited, substantive 'no' based on decommissioning and single-pass limitations, but it misses the criterion's specific concern by claiming source URLs are exposed rather than noting that built-in search makes citations hard by not exposing them, so it has a notable gap. | Q11: The answer concludes correctly with cited evidence that Groq's built-in search is too limited for citation-critical research, but it does not explicitly note that the tool returns answers without exposing source URLs, a key part of the criterion.
A12: hard-search-apis | B12: Multi-part | C12: Compare Exa, Tavily and Brave as the search backend for a research agent that must cite its sources. Cover per-request price, free tier, and how each one's result format affects citation, then recommend one. | D12: Covers all three providers on all three dimensions - price, free tier, result format - with figures, and ends with a reasoned recommendation. Missing a provider or leaving a dimension unaddressed for any provider is a gap. | E12: =IF(AND(ISNUMBER(F12),ISNUMBER(G12)),"Ya","Tidak") | F12: 3 | G12: 3 | H12: =IF(E12="Ya",G12-F12,"") | I12: 0.05046 | J12: 0.06402 | K12: 279.8 | L12: 749.1 | M12: facts | N12: facts | O12: =IF(OR(N12="",M12="bebas"),"",IF(M12=N12,"Ya","Tidak")) | P12: The answer covers Exa, Tavily, and Brave across price, free tier, and result format with cited figures and ends with a reasoned recommendation. | Q12: The answer covers Exa, Tavily, and Brave across per-request price, free tier, and citation-relevant result format with specific figures and citations, then gives a clear, reasoned recommendation.
A13: hard-model-landscape | B13: Multi-part | C13: For an agent that plans, calls tools repeatedly, and writes long reports, compare DeepSeek V4, Claude, and one open-weight alternative on price, tool-calling reliability, and context window. Say which you would pick for the planning role and why. | D13: Names three distinct model families and addresses all three dimensions for each, with concrete figures where they exist. Distinguishes tool-calling reliability from general coding benchmarks. Ends with a pick and a reason tied to the planning role. | E13: =IF(AND(ISNUMBER(F13),ISNUMBER(G13)),"Ya","Tidak") | F13: 3 | G13: 2 | H13: =IF(E13="Ya",G13-F13,"") | I13: 0.06293 | J13: 0.06022 | K13: 298.8 | L13: 804.1 | M13: facts | N13: facts | O13: =IF(OR(N13="",M13="bebas"),"",IF(M13=N13,"Ya","Tidak")) | P13: The answer names three distinct model families, provides concrete cited figures for price, context window, and tool-calling reliability for each, explicitly distinguishes tool-calling benchmarks from general coding, and ends with a planning-role pick backed by those tradeoffs. | Q13: The answer gives a strong, cited comparison for DeepSeek V4 and Qwen across price, tool-calling reliability, and context, but it does not actually address Claude on those dimensions beyond stating no evidence was found, so it falls short of the three-way comparison required.
A14: hard-chinook-market | B14: Multi-part | C14: Find the top 3 countries by invoice revenue in the chinook database, then describe what the recorded-music market looks like in each of those countries today, and note where the database's ranking diverges from the real market. | D14: Gets the top 3 countries from the database with figures, gives current market context for each of the three separately, and explicitly compares the database ranking against real-world market size. Covering only one or two countries is a gap. | E14: =IF(AND(ISNUMBER(F14),ISNUMBER(G14)),"Ya","Tidak") | F14: 3 | G14: 3 | H14: =IF(E14="Ya",G14-F14,"") | I14: 0.02643 | J14: 0.12179 | K14: 107.5 | L14: 846.5 | M14: facts | N14: facts | O14: =IF(OR(N14="",M14="bebas"),"",IF(M14=N14,"Ya","Tidak")) | P14: The answer accurately reports the Chinook top-3 with figures, gives cited current market context for the US, Canada, and France separately, and explicitly compares the database ranking to real-world rankings. | Q14: The answer provides the Chinook top 3 with revenue figures, gives current cited market context for the US, Canada, and France separately, and explicitly compares the database ranking with the real-world IFPI top markets.
A15: hard-mcp-timeline | B15: Multi-part | C15: Trace how the Model Context Protocol went from launch to its 2026 state: what drove adoption, how large the ecosystem got, and what the 2026-07-28 specification changed for people building agents. | D15: Covers three stages - launch and early adoption, ecosystem scale with a figure, and the specific 2026-07-28 spec changes - and connects them into a causal account rather than three disconnected facts. | E15: =IF(AND(ISNUMBER(F15),ISNUMBER(G15)),"Ya","Tidak") | F15: 3 | G15: 3 | H15: =IF(E15="Ya",G15-F15,"") | I15: 0.03892 | J15: 0.13107 | K15: 311.8 | L15: 825.7 | M15: facts | N15: facts | O15: =IF(OR(N15="",M15="bebas"),"",IF(M15=N15,"Ya","Tidak")) | P15: The answer covers launch and early adoption drivers, provides concrete ecosystem figures with citations, details the 2026-07-28 spec changes, and links adoption drivers to ecosystem growth in a coherent account. | Q15: The answer thoroughly traces launch, early adoption drivers, quantified ecosystem growth, and the 2026-07-28 spec changes, weaving them into a causal account with extensive citations.
A16: hard-lending-compare | B16: Multi-part | C16: Compare the rise in fintech lending defaults in Indonesia with the situation in at least two other Asian markets. Cover the default figures, what regulators blamed, and what each regulator did about it. | D16: Covers Indonesia plus at least two other named Asian markets, and for each gives a default figure, a stated cause, and a regulatory response. Treating Indonesia in depth while mentioning others in passing is a gap. | E16: =IF(AND(ISNUMBER(F16),ISNUMBER(G16)),"Ya","Tidak") | F16: 3 | G16: 3 | H16: =IF(E16="Ya",G16-F16,"") | I16: 0.0629 | J16: 0.16177 | K16: 322.4 | L16: 1185.2 | M16: facts | N16: facts | O16: =IF(OR(N16="",M16="bebas"),"",IF(M16=N16,"Ya","Tidak")) | P16: The answer covers Indonesia, India, and China in comparable depth, giving cited default or delinquency figures, regulator-attributed causes, and regulatory responses for each. | Q16: The answer thoroughly covers Indonesia, India, and the Philippines, giving cited default figures, stated causes, and regulatory responses for each, fully meeting the criterion.
A17: debate-ai-credit | B17: Judgement (debate) | C17: Should banks use AI models to approve or reject consumer loans? | D17: Gives substantive, sourced evidence on both sides - at least two real points for and two against - engages with the strongest counter-argument rather than ignoring it, and ends with a clear verdict that follows from weighing the evidence. One-sided coverage, a straw-man opposing side, or a verdict that just restates both sides is a gap. Expected points include speed and financial inclusion on one side, and bias, explainability and regulatory risk on the other. | E17: =IF(AND(ISNUMBER(F17),ISNUMBER(G17)),"Ya","Tidak") | F17: 3 | G17: 3 | H17: =IF(E17="Ya",G17-F17,"") | I17: 0.00397 | J17: 0.06121 | K17: 46.2 | L17: 450.8 | M17: debate | N17: debate | O17: =IF(OR(N17="",M17="bebas"),"",IF(M17=N17,"Ya","Tidak")) | P17: Provides multiple cited benefits and risks, directly engages the fairness/bias counterargument, and reaches a clear conditional verdict supported by the evidence. | Q17: The answer provides multiple sourced points on both sides, engages the strongest fairness counter-argument directly, and reaches a clear conditional verdict from the evidence.
A18: debate-paylater | B18: Judgement (debate) | C18: Should Indonesia restrict buy-now-pay-later (paylater) services for young borrowers? | D18: Gives substantive, sourced evidence on both sides - at least two real points for and two against - engages with the strongest counter-argument rather than ignoring it, and ends with a clear verdict that follows from weighing the evidence. One-sided coverage, a straw-man opposing side, or a verdict that just restates both sides is a gap. Expected points include consumer debt and default figures on one side, and credit access and existing OJK rules on the other. | E18: =IF(AND(ISNUMBER(F18),ISNUMBER(G18)),"Ya","Tidak") | F18: 2 | G18: 3 | H18: =IF(E18="Ya",G18-F18,"") | I18: 0.06243 | J18: 0.05139 | K18: 172.2 | L18: 554.5 | M18: debate | N18: debate | O18: =IF(OR(N18="",M18="bebas"),"",IF(M18=N18,"Ya","Tidak")) | P18: The answer provides strong, well-cited evidence for restricting paylater (debt/default figures, youth demographics, financial literacy, OJK rules) and at least one real counterpoint on credit access, but it lacks a second substantive sourced point against restriction and admits the downside case is unsupported rather than engaging the strongest counterargument. | Q18: It gives multiple cited arguments for and against, directly addresses counterarguments on NPF trends and age targeting, and reaches a clear evidence-based verdict.
A19: debate-junior-devs | B19: Judgement (debate) | C19: Is it a good idea for companies to replace junior software developers with AI coding agents? | D19: Gives substantive, sourced evidence on both sides - at least two real points for and two against - engages with the strongest counter-argument rather than ignoring it, and ends with a clear verdict that follows from weighing the evidence. One-sided coverage, a straw-man opposing side, or a verdict that just restates both sides is a gap. Expected points include productivity evidence on one side, and code quality, review burden and the talent pipeline on the other. | E19: =IF(AND(ISNUMBER(F19),ISNUMBER(G19)),"Ya","Tidak") | F19: 3 | G19: 3 | H19: =IF(E19="Ya",G19-F19,"") | I19: 0.00809 | J19: 0.10603 | K19: 66.2 | L19: 582.7 | M19: debate | N19: debate | O19: =IF(OR(N19="",M19="bebas"),"",IF(M19=N19,"Ya","Tidak")) | P19: The answer provides cited evidence on both sides, addresses the strongest counterarguments about process redesign and continued junior hiring, and ends with a clear, evidence-weighed verdict against blanket replacement. | Q19: The answer provides multiple sourced points on both sides, directly rebuts the strongest pro-replacement arguments, and reaches a clear, evidence-weighted verdict against generally replacing junior developers. | R19: Jalan pertama skor 0: API mengembalikan jawaban kosong. Dijalankan ulang setelah perbaikan (balasan kosong dicoba ulang).
A20: debate-multi-agent | B20: Judgement (debate) | C20: Is a multi-agent architecture worth it over a single agent for LLM research tasks? | D20: Gives substantive, sourced evidence on both sides - at least two real points for and two against - engages with the strongest counter-argument rather than ignoring it, and ends with a clear verdict that follows from weighing the evidence. One-sided coverage, a straw-man opposing side, or a verdict that just restates both sides is a gap. Expected points include breadth, parallelism and context isolation on one side, and token cost, coordination failures and lost shared context on the other. | E20: =IF(AND(ISNUMBER(F20),ISNUMBER(G20)),"Ya","Tidak") | F20: 3 | G20: 2 | H20: =IF(E20="Ya",G20-F20,"") | I20: 0.00351 | J20: 0.04118 | K20: 37 | L20: 300.1 | M20: debate | N20: debate | O20: =IF(OR(N20="",M20="bebas"),"",IF(M20=N20,"Ya","Tidak")) | P20: The answer supplies multiple cited points for and against multi-agent systems, addresses the pro-MAS counterargument directly, and ends with a clear conditional verdict. | Q20: The answer is well-sourced and clear on the case against multi-agent architectures, but it only provides one substantive affirmative point rather than the required two, leaving the for side underdeveloped despite engaging the strongest counter-argument.
A21: debate-nuclear-id | B21: Judgement (debate) | C21: Should Indonesia build nuclear power plants as part of its energy transition? | D21: Gives substantive, sourced evidence on both sides - at least two real points for and two against - engages with the strongest counter-argument rather than ignoring it, and ends with a clear verdict that follows from weighing the evidence. One-sided coverage, a straw-man opposing side, or a verdict that just restates both sides is a gap. Expected points include baseload low-carbon power and energy demand on one side, and cost, seismic risk, waste and public acceptance on the other. | E21: =IF(AND(ISNUMBER(F21),ISNUMBER(G21)),"Ya","Tidak") | F21: 3 | G21: 3 | H21: =IF(E21="Ya",G21-F21,"") | I21: 0.01708 | J21: 0.09508 | K21: 96.7 | L21: 507.3 | M21: debate | N21: debate | O21: =IF(OR(N21="",M21="bebas"),"",IF(M21=N21,"Ya","Tidak")) | P21: The answer supplies multiple cited points on both sides (low-carbon baseload, system-cost savings, uranium/SMR potential versus seismic risk, public acceptance, institutional readiness, and SMR cost uncertainty), engages the safety-cost-governance objections by conditioning its verdict on strict safeguards and piloting, and ends with a clear, evidence-based conditional yes. | Q21: The answer provides well-sourced arguments on both sides, engages directly with the strongest counterarguments on planning, cost, reactor size, and safety, and reaches a clear conditional verdict based on the evidence. | R21: Jalan pertama skor 0: API mengembalikan jawaban kosong. Dijalankan ulang setelah perbaikan (balasan kosong dicoba ulang).
A22: sources-deepfake | B22: News + papers | C22: What does recent research say about how well deepfake detectors catch face-swap attacks in identity verification, and have banks or regulators reported real deepfake fraud cases? | D22: Cites at least one research study with a concrete finding on detection accuracy or generalisation, and at least one real reported case or regulator alert about deepfake fraud in banking or finance. Missing either the research side or the real-world side is a gap. | E22: =IF(AND(ISNUMBER(F22),ISNUMBER(G22)),"Ya","Tidak") | F22: 3 | G22: 3 | H22: =IF(E22="Ya",G22-F22,"") | I22: 0.02862 | J22: 0.1059 | K22: 176.5 | L22: 631.3 | M22: facts | N22: facts | O22: =IF(OR(N22="",M22="bebas"),"",IF(M22=N22,"Ya","Tidak")) | P22: The answer cites specific research findings on detection accuracy and generalization, and separately cites FinCEN and multiple reported bank deepfake fraud cases, fully meeting both sides of the criterion. | Q22: The answer cites multiple research studies with concrete detection accuracy and generalisation findings and multiple real reported cases and regulator alerts involving deepfake fraud in banking/finance, satisfying both required elements.
A23: sources-lending | B23: News + papers | C23: What did the latest news say about OJK's fintech lending default rate (TWP90), and what does academic research identify as the main drivers of online lending defaults? | D23: Gives a recent TWP90 figure or news report attributed to OJK, and separately summarises drivers of online lending default identified by academic research. Missing either the news side or the research side is a gap. | E23: =IF(AND(ISNUMBER(F23),ISNUMBER(G23)),"Ya","Tidak") | F23: 0 | G23: 2 | H23: =IF(E23="Ya",G23-F23,"") | I23: 0.00666 | J23: 0.06588 | K23: 54.4 | L23: 1007.7 | M23: facts | N23: facts | O23: =IF(OR(N23="",M23="bebas"),"",IF(M23=N23,"Ya","Tidak")) | P23: The answer cites future-dated August–October 2026 news and figures that cannot exist as of May 2026, so the TWP90 claim appears fabricated and the evidence is not credible. | Q23: The answer substantially covers both the recent OJK TWP90 figure and academic drivers of online lending defaults, but the factual claims and research findings are uncited. | R23: Skor 0 karena bug penilai: mengira berita Agustus-Oktober 2026 'dari masa depan'. Penilai sudah diperbaiki, soal ini belum dinilai ulang.

Sheet Jawaban 1 agent
A1: ID | B1: Kelompok | C1: Pertanyaan | D1: Skor | E1: Alasan penilai | F1: Jawaban lengkap
A2: db-artists | B2: Simple lookups | C2: Which artist has the most tracks in the chinook database, and how many? | D2: 3 | E2: all expected values present | F2: Iron Maiden has the most tracks in the Chinook database, with 213 tracks [1]. Sources: [1] internal database (chinook)
A3: db-revenue | B3: Simple lookups | C3: What are the top 3 countries by total invoice revenue in the chinook database? | D3: 3 | E3: all expected values present | F3: The top three countries by total invoice revenue in the Chinook database are the USA with $523.06, Canada with $303.96, and France with $195.10 [1]. This is based on summing the Total column from the Invoice table grouped by BillingCountry. Sources: [1] internal database (chinook)
A4: db-employees | B4: Simple lookups | C4: How many employees are in the chinook database? | D4: 3 | E4: all expected values present | F4: The chinook database contains 8 employees [1]. Sources: [1] internal database (chinook)
A5: db-northwind | B5: Simple lookups | C5: How many products are in the northwind database? | D5: 3 | E5: all expected values present | F5: The Northwind database contains **77 products** [1]. Sources: [1] internal database (northwind)
A6: web-ojk | B6: Simple lookups | C6: What did Indonesia's OJK say caused the rise in bad loans at digital lending platforms, and roughly what was the TWP90 level in 2026? | D6: 3 | E6: The answer identifies borrower repayment capacity as the main driver with OJK citations and provides 2026 TWP90 figures around 4.4–4.7 percent, matching the requested 4–5 percent range. | F6: Indonesia's OJK attributed the rise in bad loans at digital lending platforms mainly to a decline in borrowers' repayment capacity. Agusman, OJK's executive head of supervision for financing institutions, venture capital, microfinance and other financial services, said the increase in non-performing financing was influenced by "menurunnya kemampuan bayar sebagian borrower" — the declining ability of some borrowers to pay [1][3][5]. He also said the dominance of problem loans in the productive segment reflected business characteristics, especially MSMEs' reliance on cash flow and market conditions, rather than solely data limitations [1]. OJK pushed platforms to strengthen governance and risk management, including better e-KYC and credit scoring, so lending would be more selective and prudent [1][5]. On the TWP90 level in 2026, reported figures were roughly in the mid-4 percent range and rising: 4.38 percent in January 2026 [1][5], 4.62 percent in April 2026 [4], and 4.73 percent in August 2026 [3]. By comparison, January 2025 was reported at 2.59 percent [1][5]. So a rough 2026 range would be about 4.4–4.7 percent, with the precise figure varying by month. One article also cited 4.33 percent in November, up from 2.52 percent a year earlier [2], though its year label is less clear. Sources: [1] Pembiayaan Bermasalah Industri Pindar Melonjak, Begini Penjelasan Bos OJK! - https://mediaasuransinews.co.id/pembiayaan/pembiayaan-bermasalah-industri-pindar-melonjak-begini-penjelasan-bos-ojk/ [2] OJK threatens ‘corrective measures’ as P2P defaults rise - Tech - The Jakarta Post - https://www.thejakartapost.com/business/2026/01/13/ojk-threatens-corrective-measures-as-p2p-defaults-rise [3] Kredit Macet Pinjol Naik 4,73%, OJK Soroti Kemampuan Bayar Borrower - https://finansial.bisnis.com/read/20261009/563/2011301/kredit-macet-pinjol-naik-473-ojk-soroti-kemampuan-bayar-borrower [4] OJK flags capital gaps and high TWP90 in fintech lending sector - The Indonesian Post - https://indonesianpost.com/2026/06/08/ojk-special-supervision-fintech-lenders-capital-bad-loans-indonesia/ [5] Kata OJK soal Kredit Macet Industri Pinjol Naik 61% hingga Denda oleh KPPU - https://finansial.bisnis.com/read/20260408/563/1965206/kata-ojk-soal-kredit-macet-industri-pinjol-naik-61-hingga-denda-oleh-kppu
A7: web-mcp | B7: Simple lookups | C7: What is the Model Context Protocol and how widely is it adopted? | D7: 3 | E7: The answer clearly explains MCP as a standard for connecting AI models to tools and data and provides well-cited adoption figures including thousands of public servers, with appropriate nuance about usage quality. | F7: The Model Context Protocol (MCP) is an open-source standard introduced by Anthropic in November 2024 for connecting AI applications and agents to external data sources, tools, and workflows. Official documentation describes it as a "USB-C port for AI applications": a shared interface that lets AI systems such as Claude or ChatGPT access files, databases, APIs, search tools, and other systems without building a custom integration for each one [1][2][5]. Architecturally, it is a client-server protocol: an MCP host, such as Claude Desktop or Visual Studio Code, creates MCP clients that connect to MCP servers; servers expose tools, resources, and prompts over JSON-RPC 2.0, using local stdio transport or remote Streamable HTTP transport [3][4]. Its stated goal is to replace fragmented, one-off integrations with a single standardized protocol [2]. On adoption, the evidence points to rapid and broad supply-side uptake. Anthropic open-sourced MCP in late 2024, and official sources say it is supported by AI assistants such as Claude and ChatGPT and developer tools such as Visual Studio Code and Cursor [1][2]. Reporting also notes adoption by major AI providers including OpenAI and Google DeepMind, and Anthropic donated MCP to the Agentic AI Foundation, a fund under the Linux Foundation, in December 2025 [5]. One industry analysis counted published MCP servers growing from 3 in October 2024 to 6,878 by November 2025, about 2,200% growth in 13 months [6][10]. The official TypeScript SDK was reported at roughly 700,000 weekly npm downloads, and the Smithery discovery platform reportedly saw server creation triple in March 2025 alone [8]. A 2025 academic-style measurement study crawled six MCP marketplaces and, after filtering, analyzed about 8,400 valid projects: 8,060 servers and 341 clients [7]. However, the raw adoption numbers overstate real usage and quality. The measurement study found that more than half of raw marketplace listings were invalid, placeholders, abandoned, or otherwise low-value [7]. The O'Reilly analysis of 2,874 MCP servers found that the top 10 servers accounted for 45.7% of all GitHub stars, and the top 10% accounted for 88.3%, indicating highly concentrated attention and likely usage [9]. Smithery data showed that only 8 of its 2,500+ servers had passed 50,000 installs, with usage following a power-law distribution and clustering around developer-focused categories such as code, file search, and automation [8]. Enterprise telemetry from another report estimated that in a typical 10,000-person organization, 15.28% of employees run at least one local MCP server, totaling about 3,056 deployments, and that 38% of those servers were unofficial implementations from unknown authors, which the authors frame as a security risk [6][10]. Overall, MCP is widely adopted as an emerging standard by major AI vendors and the developer ecosystem, and its server ecosystem has grown extremely quickly. At the same time, actual end-user usage appears concentrated, technical, and noisier than headline server counts suggest, with meaningful security and quality concerns still unresolved [6][7][8][9][10]. Sources: [1] What is the Model Context Protocol (MCP)? - Model Context Protocol - https://modelcontextprotocol.io/docs/2025-03-26/getting-started/intro [2] Introducing the Model Context Protocol \ Anthropic - https://www.anthropic.com/research/model-context-protocol [3] Overview - Model Context Protocol - https://modelcontextprotocol.io/specification/2025-11-25/basic [4] Architecture overview - Model Context Protocol - https://modelcontextprotocol.io/docs/2025-03-26/learn/architecture [5] Model Context Protocol - https://en.wikipedia.org/wiki/Model_Context_Protocol [6] MCP Servers: What We Found When We Actually Looked - https://www.clutch.security/blog/mcp-servers-what-we-found-when-we-actually-looked [7] A Measurement Study of Model Context Protocol Ecosystem - https://arxiv.org/html/2509.25292v3 [8] What MCP’s Rise Really Shows: A Tale of Two Ecosystems - https://www.madrona.com/what-mcps-rise-really-shows-a-tale-of-two-ecosystems/ [9] MCP in Practice – O’Reilly - https://www.oreilly.com/radar/mcp-in-practice/ [10] Model Context Protocol: A View from the Trenches - https://145696913.fs1.hubspotusercontent-eu1.net/hubfs/145696913/Clutch%20Security%20-%20MCP%20A%20View%20From%20The%20Trenches%202025.pdf
A8: web-deepseek | B8: Simple lookups | C8: How does DeepSeek V4 pricing compare to Anthropic's Claude models? | D8: 3 | E8: Provides cited per-million-token prices for both DeepSeek V4 and Claude models and correctly concludes DeepSeek is roughly an order of magnitude cheaper for comparable mid/top tiers, with the low-end caveat supported. | F8: DeepSeek V4 is generally much cheaper than Anthropic's Claude models, especially in the mid- and top tiers, but the size of the gap depends on which price sheet you use. At the official/list rates cited when V4 launched in April 2026, DeepSeek V4-Flash was $0.14 per 1M input tokens and $0.28 per 1M output tokens, and V4-Pro was $1.74 input / $3.48 output at list (or $0.435/$0.87 during a 75% promotional period) [3][5][7]. Against that, Anthropic's Claude line was Haiku 4.5 at $1/$5, Sonnet 4.6 at $3/$15, and Opus 4.7 at $5/$25 [3][4]. That means V4-Pro output was roughly 7x cheaper than Opus 4.7, and V4-Flash output was about 18x cheaper than Sonnet 4.6 and about 89x cheaper than Opus 4.7 [3][5]. More recent pricing complicates the low-end comparison. DeepSeek's current official API pricing for deepseek-flash (DeepSeek-V4.1-Flash-1017) uses peak/off-peak billing: cache-miss input is $0.15 off-peak / $0.30 peak, and output is $0.60 off-peak / $1.20 peak; deepseek-v4-pro is $0.66/$1.32 input and $1.98/$3.96 output, with cache-hit rates as low as $0.003 for Flash and $0.022 for Pro [6][10]. On the current OpenRouter model list (Oct 15, 2026), Anthropic's cheapest model, Claude Haiku 5.5, is $0.10 in / $0.50 out, which slightly undercuts DeepSeek's official Flash off-peak rate, but DeepSeek's cached-input prices are much lower, and mid/top-tier Claude models remain far more expensive: Sonnet 5.5 is $2/$10, Opus 5.5 is $4/$20, Opus 5 is $5/$25, and Fable 5.1 is $10/$50 [2][6]. Using third-party hosts or marketplaces widens DeepSeek's advantage. The same OpenRouter snapshot lists DeepSeek V4 Flash 0731 via DeepInfra at $0.06 in / $0.18 out, making it cheaper than Claude Haiku 5.5; the median DeepSeek model was $0.285 in / $1.00 out, against $4.50 in / $22.50 out for Claude, and the priciest listed DeepSeek was $0.45/$3.48 versus $15/$75 for Claude Opus 4.1 on Bedrock [2]. A worked 1M-call/month example estimated DeepSeek V4-Flash at about $117.60, compared with about $5,700 for Claude Sonnet 4.6 and roughly $9,500 for Opus 4.7; even stacking Anthropic's caching and batch discounts still left Sonnet 4.6 far above V4-Flash [3]. Anthropic does offer broad caching and batch discounts, while DeepSeek's current docs emphasize peak/off-peak and cache-hit pricing rather than an equivalent broad batch program [2][3][6]. Bottom line: for cost-sensitive workloads, DeepSeek V4 is dramatically cheaper than Claude's frontier and mid-tier models, with the largest gaps in output tokens. The only place the comparison tightens is at the very cheapest Claude model, Haiku 5.5, which can beat DeepSeek's official Flash list price but not the cheapest third-party-hosted DeepSeek V4 Flash rates [2][6]. Sources: [1] Models & Pricing | DeepSeek API Docs - https://api-docs.deepseek.com/quick_start/pricing [2] Claude vs DeepSeek API pricing, compared model by model . Alexey Shurov - https://shurco.ai/tools/llm-api-pricing/compare/claude-vs-deepseek/ [3] DeepSeek vs Anthropic: 2026 Price & Performance - https://deepseekai.guide/comparisons/deepseek-vs-anthropic/ [4] DeepSeek V4 is here: How it compares to ChatGPT, Claude, Gemini - https://tech.yahoo.com/ai/gemini/articles/deepseek-v4-compares-chatgpt-claude-215424317.html [5] Claude Opus 4.7 vs DeepSeek V4: A Complete Comparison - https://www.datacamp.com/blog/deepseek-v4-vs-claude-opus-4-7 [6] Models & Pricing | DeepSeek API Docs - https://api-docs.deepseek.com/quick_start/pricing/ [7] DeepSeek | API Platform - https://www.deepseek.com/en/platform/ [8] 模型 & 价格 | DeepSeek API Docs - https://api-docs.deepseek.com/zh-cn/quick_start/pricing [9] Your First API Call | DeepSeek API Docs - https://api-docs.deepseek.com/ [10] Model pricing - https://www.tencentcloud.com/document/product/1300/78937
A9: mixed-genre | B9: Simple lookups | C9: Which music genre has the most tracks in the chinook database, and what is that genre's real-world popularity today? | D9: 3 | E9: The answer correctly identifies Rock as the Chinook top genre with 1,297 tracks and adds cited, current real-world popularity context showing rock as a strong second genre rather than the top genre. | F9: Chinook’s largest genre is **Rock**, with **1,297 tracks** [1]. In today’s real-world music market, rock is a major genre but not the single most popular. Luminate’s 2025 U.S. year-end data put **R&B/Hip-Hop first with 25.5% of on-demand audio streams**, while **Rock was second at 15.3%** and roughly flat year-over-year [6]. A Spotify-focused 2025 summary likewise ranked global genres as **Hip-Hop/R&B first and Rock second**, followed by Pop, Latin, and Country [4]. Rock did have strong momentum: it grew U.S. streaming share by 6.4% year-over-year in 2025, and Luminate described it as the “largest growth genre” of the year [2][5]. However, the most-streamed songs globally are still dominated by pop, hip-hop, and K-pop [5]. So the Chinook leader remains a top-tier real-world genre today, but it is better described as a strong second place rather than the most popular genre overall. Sources: [1] internal database (chinook) [2] Luminate Year-End Music Report 2025 - https://view.ceros.com/luminate-data/luminate-year-end-music-report-2025-1 [3] Global music streams hit 5 trillion in 2025 | AP News - https://apnews.com/article/music-listening-habits-2025-christian-rock-latin-a5e06a001705cd7e5d3854d8fab901b8 [4] Spotify-Statistiken: Nutzer-, Künstler- und Marktdaten (2025) - https://www.socialplug.io/de/blog/spotify-statistiken [5] Rock Music Just Had One of Its Best Streaming Years Despite Being 'Dead' - Parade - https://parade.com/news/rock-music-just-had-one-of-its-best-streaming-years-despite-being-dead [6] etl/luminate__ye2025_us_genre_share_to_parquet.py - https://github.com/joaoroquedasilvajunior/atana-data/blob/main/etl/luminate__ye2025_us_genre_share_to_parquet.py
A10: unanswerable | B10: Simple lookups | C10: What was the exact revenue of the chinook music store in the third quarter of 2027? | D10: 3 | E10: The answer correctly states that no Q3 2027 data exists because the invoice table's latest date is 2025-12-22, and it cites the internal database rather than inventing a revenue figure. | F10: The Chinook database contains no invoices for the third quarter of 2027. A query summing invoice totals for July 1 through September 30, 2027 returned no data, and the invoice table's latest date is 2025-12-22 [1]. Therefore, within the database, the exact recorded revenue for Q3 2027 is $0.00; there are no 2027 transactions to report. Sources: [1] internal database (chinook)
A11: contradiction | B11: Simple lookups | C11: Is Groq's built-in web search a good choice for a deep research agent that needs citations? | D11: 2 | E11: The answer gives a well-cited, substantive 'no' based on decommissioning and single-pass limitations, but it misses the criterion's specific concern by claiming source URLs are exposed rather than noting that built-in search makes citations hard by not exposing them, so it has a notable gap. | F11: Short answer: No—at least not for a new deep-research build right now. Groq's built-in web search had promising citation features on paper, but it is tied to systems that Groq says have been decommissioned, and it was never a deep multi-page browsing tool. What it offered: The Web Search docs say API responses automatically include citations with a complete list of referenced sources, and `citation_options` can be enabled or disabled [1][2]. Raw search results are also exposed via `message.executed_tools[0].search_results`, including titles, URLs, snippets, and relevance scores, which lets a developer verify sources or build custom citations [1][7]. Groq says the search is powered by Tavily, a search API designed for language-model citation and ranking [1][7]. There are also `include_domains` and `exclude_domains` settings to constrain sources [2][7]. Why it is weak for deep research: Groq's web search performs a single search and retrieves text snippets, unlike its Browser Search tool, which navigates sites interactively [1][7]. Deep research agents usually need iterative querying, page navigation, cross-source synthesis, and stronger provenance control. The built-in web search runs server-side with Groq handling orchestration, which is convenient but gives the agent less control over the research loop [1][3][7]. It is also not available for HIPAA-covered or regional/sovereign endpoint use [1][3][7]. The decisive problem is availability. Built-in web search is documented as supported only on `groq/compound` and `groq/compound-mini` [1][7], and Groq's own deprecation and model pages state that both were decommissioned on September 21, 2026 [6][9][10][11]. The deprecation list shows no recommended replacement model ID [9][12]. Some Web Search documentation still lists those systems as supported, so Groq's docs appear inconsistent, but the deprecation notice, changelog, and model pages are explicit that the endpoints no longer work [1][6][7][9][10][11]. There is a separate built-in Browser Search tool on `openai/gpt-oss` models, but that is a different interactive tool, and the cited docs do not advertise the same automatic citation pipeline; it is also not compatible with structured outputs [3][5]. Overall, if reliable citations are a hard requirement, Groq's built-in web search is not a good foundation right now because it is effectively unavailable and was a snippet-level single search rather than a deep research loop. Sources: [1] Web Search - GroqDocs - https://console.groq.com/docs/web-search [2] API Reference - GroqDocs - https://console.groq.com/docs/api-reference [3] Groq Built-In Tools - GroqDocs - https://console.groq.com/docs/tool-use/built-in-tools [4] qai-sdk 0.1.26 - Docs.rs - https://docs.rs/crate/qai-sdk/latest/source/examples/groqcloud_web_search.rs [5] Browser Search - GroqDocs - https://console.groq.com/docs/tool-use/built-in-tools/browser-search [6] Compound - GroqDocs - https://console.groq.com/docs/compound/systems/compound [7] Web Search - GroqDocs - https://console.groq.com/docs/tool-use/built-in-tools/web-search [8] Use Cases - GroqDocs - https://console.groq.com/docs/compound/use-cases [9] Model Deprecation - GroqDocs - https://console.groq.com/docs/deprecations [10] Compound Mini - GroqDocs - https://console.groq.com/docs/compound/systems/compound-mini [11] Compound Changelog - GroqDocs - https://console.groq.com/docs/changelog/compound [12] groq/compound-mini shut down on Sep 21, 2026 (Groq) · ModelClock - https://model-clock.com/models/groq/groq%2Fcompound-mini
A12: hard-search-apis | B12: Multi-part | C12: Compare Exa, Tavily and Brave as the search backend for a research agent that must cite its sources. Cover per-request price, free tier, and how each one's result format affects citation, then recommend one. | D12: 3 | E12: The answer covers Exa, Tavily, and Brave across price, free tier, and result format with cited figures and ends with a reasoned recommendation. | F12: Comparison: Exa, Tavily, and Brave as search backends for a citation-required research agent. Per-request price (public list, pay-as-you-go unless noted): - Exa: prepaid credits. /search lite and instant are $4 per 1,000 requests, i.e. $0.004 per request for up to 10 results; auto and fast are $7 per 1,000 ($0.007); each result above 10 costs $1 per 1,000; AI page summaries cost $1 per 1,000 pages; /answer is $5 per 1,000 ($0.005); /contents is $1 per 1,000 pages per content type [1][3][4]. A 15-result auto call would be the $0.007 base plus 5 extra results at $0.001 each, so $0.012 before any summaries. - Tavily: credit-based. Pay-as-you-go is $0.008 per credit; basic search uses 1 credit ($0.008) and advanced uses 2 credits ($0.016) [6][8]. Monthly plans lower the per-credit price to $0.0075 down to $0.005, making basic about $0.005 to $0.0075 [6]. Tavily Research is separate and dynamic: mini 4-110 credits, pro 15-250 credits per request [6]. - Brave: the Search plan includes Web, News, Images, Videos, and LLM Context at $5 per 1,000 requests ($0.005) [11][20]. The Answers plan is $4 per 1,000 web searches plus $5 per million input/output tokens [11][13][20]. Brave has also published a vendor-run FreshQA comparison claiming its all-in cost per 1,000 questions is much lower than Exa and Tavily, but that figure includes model token costs and is from Brave's own materials [11]. Free tier: - Exa: $10 in credits every month, resetting on the first of the month and not rolling over, plus a one-time $10 onboarding bonus for the first team [1][3]. At lite rates that is up to 2,500 searches per month; at auto it is roughly 1,428 [1][4]. The free tier does not include Exa Snapshot [3]. - Tavily: free Researcher plan of 1,000 credits per month, no credit card required [6][7]. That is 1,000 basic searches or 500 advanced searches per month. - Brave: current documentation says there is no standalone free plan; each plan gets $5 in free credits that renew monthly, equivalent to about 1,000 Search requests, and using it without a prepaid balance requires entering a card and setting prepay to $0 [18][20]. Older pages describing 2,000 free queries per month are outdated [14][17]. How result format affects citation: - Exa is the strongest for citation plumbing. Search results expose title, url, publishedDate, author, text, highlights, score, and optional page summary [2][5]. More importantly, if you supply an outputSchema, the response includes an output.grounding array with field-level citation entries of url and title plus a confidence level, which supports per-claim attribution. The /answer endpoint returns an answer plus a citations array of source result objects [1][2][5]. That means a research agent can cite either per-field or per-answer without rebuilding a mapping from a separate results list. - Tavily is source-list style. Its results provide title, url, content, score, optional raw_content, and optional favicon/images; published_date is available only if include_published_date is enabled and defaults off except for news [8][21][22]. It can return an include_answer LLM summary grounded in the results, but the response is an answer string plus a flat results array, not sentence-level citations; Tavily materials say the answer only references returned results and advise displaying the top sources alongside it [23]. An agent would need to map claims to sources itself. - Brave depends on which endpoint you use. The classic Web Search endpoint returns title, url, description, and optional extra snippets; it does not pull full raw page content, so citations based on Search API alone are conventional URL-plus-snippet citations [12][14]. The LLM Context endpoint returns extracted, ranked context with a URL and timestamp and supports token budgets, which gives traceable evidence snippets [11][20]. The Answers endpoint is the explicit citation path: it is described as grounded with citations and streaming [11][13]. Recommendation: For a research agent whose core requirement is citing sources, Exa is the best default. It has the most direct citation features (author/date metadata, page text/highlights, field-level grounding, and /answer citations) at a base search price of $0.004-$0.007, with a $10 monthly free allowance that is generous enough to test real workflows [1][2][3][5]. Tavily is the simpler low-cost option if a flat source list is acceptable and you stick to basic searches; Brave is attractive if you specifically want an independent index, token-budgeted LLM context, or privacy, but its strongest citation affordances sit in the Answers tier with variable token costs. On balance, choose Exa. Sources: [1] Pricing - Exa - https://exa.ai/docs/admin/pricing [2] Search - Exa - https://exa.ai/docs/reference/search [3] Billing and Rate Limits - Exa - https://exa.ai/docs/admin/billing [4] Exa Search API - https://exa.ai/docs/search/quickstart [5] (untitled) - https://exa.ai/docs/sdks/typescript-sdk-specification [6] Credits & Pricing - Tavily Docs - https://docs.tavily.com/documentation/api-credits [7] Tavily Pricing - https://www.tavily.com/pricing [8] (untitled) - https://docs.tavily.com/documentation/api-reference/endpoint/search [9] Basic vs. Advanced Search: What's the Difference? | Tavily Help Center - https://help.tavily.com/articles/6938147944-basic-vs-advanced-search-what-s-the-difference [10] Frequently Asked Questions - Tavily Docs - https://docs.tavily.com/faq/faq [11] Brave Search API | Brave - https://brave.com/search/api/ [12] Web Search - Brave Search API - https://api-dashboard.search.brave.com/documentation/services/web-search [13] Introducing AI Grounding with Brave Search API, providing enhanced search performance in AI applications | Brave - https://brave.com/blog/ai-grounding/ [14] How does the Brave Search API compare to other Web search API options? | Brave - https://brave.com/search/api/guides/what-sets-brave-search-api-apart/ [15] Brave Review: Private Search For Clean AI Data - https://data4ai.com/vendors/ai-search/brave-browser/ [16] Pricing - https://api-dashboard.search.brave.com/documentation/pricing [17] Brave releases its Search API, bringing independence and competition to the search landscape | Brave - https://brave.com/blog/search-api-launch/ [18] Help & Feedback - https://api-dashboard.search.brave.com/documentation/resources/help-feedback [19] Brave Search - API - https://api-dashboard.search.brave.com/app/plans [20] Brave launches most powerful search API for AI to date | Brave - https://brave.com/blog/most-powerful-search-api-for-ai/ [21] SDK Reference - Tavily Docs - https://docs.tavily.com/sdk/javascript/reference [22] SDK Reference - Tavily Docs - https://docs.tavily.com/sdk/python/reference [23] Answer citations | Tavily Api Beginner Course | The Neural Base - https://theneuralbase.com/tavily-api/learn/beginner/answer-citations/ [24] src/providers/tavily.ts - https://github.com/oritwoen/websxa/blob/1a48fb38/src/providers/tavily.ts
A13: hard-model-landscape | B13: Multi-part | C13: For an agent that plans, calls tools repeatedly, and writes long reports, compare DeepSeek V4, Claude, and one open-weight alternative on price, tool-calling reliability, and context window. Say which you would pick for the planning role and why. | D13: 3 | E13: The answer names three distinct model families, provides concrete cited figures for price, context window, and tool-calling reliability for each, explicitly distinguishes tool-calling benchmarks from general coding, and ends with a planning-role pick backed by those tradeoffs. | F13: I compared DeepSeek V4 (Pro/Flash), Anthropic Claude (Opus 5.5 and Sonnet 5.5), and GLM-5.3-Flash as the open-weight alternative. Price: DeepSeek V4-Pro is $1.74 per million input tokens and $3.48 per million output, with $0.145 per million cache hits; V4-Flash is $0.14/$0.28 with $0.028 cache hits [1][2]. Claude Opus 5.5 is $4/$20 with $0.20 cache hits, and Claude Sonnet 5.5 is $2/$10 with $0.10 cache hits [6][7][9]. GLM-5.3-Flash is much cheaper at $0.15/$0.50 with $0.03 cached input and is MIT-licensed/open-weight [14][21][24]. Claude Opus 5.5 is therefore about 2.3x DeepSeek V4-Pro on input and about 5.7x on output. Context window: All three have 1M-token input contexts: DeepSeek V4-Pro and Flash accept 1M tokens and can generate up to 384K output tokens [2][3][5]; Claude models accept 1M tokens but cap output at 128K [6][8][9]; GLM-5.3-Flash accepts 1M tokens and caps output at 128K [22][24][25]. The DeepSeek long-context case has a caveat that retrieval is not uniform across the window, with the first 256K more reliable than later parts [4]. Tool-calling reliability: On the HKUST Toolathlon-Verified benchmark, GLM-5.3-Flash leads at 78.4%, Claude Opus 4.8 is at 76.2%, DeepSeek V4-Pro is at 74.4%, and DeepSeek V4-Flash is at 70.7% [16]. A later BenchLM comparison puts Claude Opus 5.5 at 77.8% and GLM-5.3-Flash at 78.4% on the same benchmark [18]. So for pure tool syntax/selection, all are close, but GLM and Claude have a small edge over DeepSeek. DeepSeek has an architectural advantage for repeated tool calls: its XML-based tool-call schema reduces escaping/parsing errors, and it preserves interleaved reasoning across tool calls [3]. For planning depth, the picture shifts: on tool-augmented HLE, Claude Opus 5.5 scores 67.7%, DeepSeek V4-Pro 0813 scores 60.0%, and GLM-5.3-Flash scores 55.3% [19]. Pick: I would choose DeepSeek V4-Pro for the planning role. It gives the best balance for this workload: near-Claude tool-calling reliability (74.4 versus 76.2/77.8) [16][18], stronger planning/reasoning with tools than the cheaper open-weight GLM option (60.0 versus 55.3 HLE with tools) [19], a 1M context window with a much larger 384K output ceiling for long reports [2][3], and pricing that is far below Claude Opus 5.5, especially on output tokens ($3.48 versus $20) [1][2][7][9]. Claude Opus 5.5 would be the choice if absolute frontier planning quality is worth the premium, since its HLE-with-tools score is higher [19], but for a cost-sensitive agent that calls tools repeatedly and writes long reports, DeepSeek V4-Pro is the strongest practical pick. Sources: [1] 模型价格 - https://www-sg.tencentcloud.com/zh/document/product/1300/78937 [2] DeepSeek V4 API Pricing - https://apidog.com/blog/deepseek-v4-api-pricing/ [3] DeepSeek-V4: a million-token context that agents can ... - https://huggingface.co/blog/deepseekv4 [4] (untitled) - https://docs.together.ai/docs/deepseek-v4-quickstart [5] DeepSeek API Guide - https://www-sg.tencentcloud.com/document/product/1300/80633 [6] Models overview - https://platform.claude.com/docs/en/models/overview [7] Pricing - https://platform.claude.com/docs/en/about-claude/pricing [8] Context windows - https://platform.claude.com/docs/en/build-with-claude/context-windows [9] Anthropic List Prices — 2026-10-07 - https://assets.claude.com/1ef7a4a8e373004bc89d710b0a6f3f219323344f.pdf [10] Claude Platform release notes - https://platform.claude.com/docs/en/release-notes/overview [11] Open-Weight LLM Leaderboard | LMSA - https://lmsa.app/leaderboard/ [12] Best LLMs for Agents and Function Calling | Which LLM - https://whichllm.together.ai/use-case/agents-and-function-calling/best-llms [13] Cheapest Agent LLMs · Ranked by Price and Tool Use Score | BenchGecko - https://benchgecko.ai/pricing/agents [14] Best LLM for AI Agents (2026): Picks, Prices, How to Test | Promptise - https://www.promptise.com/guides/view/best-llm-for-ai-agents [15] Models with tool calling | PicksByModel - https://picksbymodel.com/tools/ [16] Toolathlon-Verified Scores — Results by Model | AIB - https://www.aib.vote/en/benchmarks/toolathlon-verified [17] LLM Stats (Toolathlon) Leaderboard · The Aggregate - https://theaggregate.ai/benchmark?slug=llm-stats-toolathlon [18] Claude Opus 5.5 vs GLM-5.3-Flash - https://benchlm.ai/compare/claude-opus-5-5-vs-glm-5-3-flash [19] Humanity's Last Exam with tools (HLE w/ tools) - https://benchlm.ai/benchmarks/hlewithtools [20] Best AI for Tool Calling 2026 - Top Function Calling Models - https://llm-stats.com/leaderboards/best-ai-for-tool-calling [21] Pricing - Overview - Z.AI DEVELOPER DOCUMENT - https://docs.z.ai/guides/overview/pricing [22] GLM-5.3-Flash/FlashX - Overview - Z.AI DEVELOPER DOCUMENT - https://docs.z.ai/guides/vlm/glm-5.3-flash [23] Z.ai API Platform — Start building with GLM-5.3 - https://z.ai/model-api [24] glm-5.3-flash (Zhipu AI) · Cloudflare AI docs · Cloudflare AI docs - https://developers.cloudflare.com/ai/models/%40cf/zai-org/glm-5.3-flash/ [25] ZHIPU/GLM-5.3-Flash Model Info-Alibaba Cloud Model Studio(Model Studio)-阿里云帮助中心 - https://help.aliyun.com/en/model-studio/glm-5-3-flash-by-zhipu
